from unittest.mock import Mock, AsyncMock
import asyncio
import sys
from pathlib import Path

# Add src to path
src_path = Path(__file__).parent
while src_path.name != "backend" and src_path.parent != src_path:
    src_path = src_path.parent
src_path = src_path / "src"

if str(src_path) not in sys.path:
    sys.path.insert(0, str(src_path))


# Import pytest with fallback to mock
pytest = None
try:
    import pytest
except ImportError:
    try:
        from common.mock_pytest import pytest
    except ImportError:
        pass

    # Mock pytest when not available
    if pytest is None:
        class MockPytest:

        def fixture(self, *args, **kwargs):
            def decorator(func):
                return func

            return decorator

        def mark(self):
            class MockMark:
                def parametrize(self, *args, **kwargs):
                    def decorator(func):
                        return func

                    return decorator

                def asyncio(self, func):
                    return func

                def slow(self, func):
                    return func

                def skip(self, reason=""):
                    def decorator(func):
                        return func

                    return decorator

            return MockMark()

        def raises(self, exception):
            class MockRaises:
                def __enter__(self):
                    return self

                def __exit__(self, *args):
                    return False

            return MockRaises()

        def skip(self, reason=""):
            def decorator(func):
                return func

            return decorator

    pytest = MockPytest()


class TestErrorHandlingAndRecovery:
    """Test error handling and recovery mechanisms"""

    @pytest.mark.asyncio
    async def test_network_failure_recovery(self):
        """Test recovery from network failures"""
        attempt_count = 0
        max_retries = 3

        async def flaky_network_call():
            nonlocal attempt_count
            attempt_count += 1

            if attempt_count < 3:
                raise ConnectionError("Network timeout")

            return {"status": "success", "data": "recovered"}

        # Implement retry with exponential backoff
        result = None
        for i in range(max_retries):
            try:
                result = await flaky_network_call()
                break
            except ConnectionError:
                if i == max_retries - 1:
                    raise
                await asyncio.sleep(0.1 * (2**i))  # Exponential backoff

        # Assert recovery
        assert result is not None
        assert result["status"] == "success"
        assert attempt_count == 3

    @pytest.mark.asyncio
    async def test_database_transaction_rollback(self):
        """Test database transaction rollback on error"""
        # Mock database
        db = Mock()
        db.begin_transaction = AsyncMock()
        db.commit = AsyncMock()
        db.rollback = AsyncMock()

        changes_made = []

        async def update_with_transaction():
            await db.begin_transaction()

            try:
                # Make some changes
                changes_made.append("change_1")
                changes_made.append("change_2")

                # Simulate error
                raise ValueError("Invalid data")

                # This code is unreachable, which is intended for the test
                # changes_made.append("change_3")
                # await db.commit()
            except Exception:
                await db.rollback()
                changes_made.clear()  # Rollback changes
                raise

        # Test rollback
        with pytest.raises(ValueError):
            await update_with_transaction()

        # Assert rollback was called and changes cleared
        db.rollback.assert_called_once()
        db.commit.assert_not_called()
        assert len(changes_made) == 0

    @pytest.mark.asyncio
    async def test_graceful_degradation(self):
        """Test graceful degradation when services fail"""
        # Mock services
        primary_service = Mock()
        fallback_service = Mock()

        primary_service.get_response = AsyncMock(
            side_effect=Exception("Service unavailable")
        )
        fallback_service.get_response = AsyncMock(
            return_value="Fallback response"
        )

        async def get_response_with_fallback(query):
            try:
                return await primary_service.get_response(query)
            except Exception:  # Fallback to simpler service
                return await fallback_service.get_response(query)

        # Test fallback
        response = await get_response_with_fallback("test query")

        # Assert fallback worked
        assert response == "Fallback response"
        primary_service.get_response.assert_called_once()
        fallback_service.get_response.assert_called_once()
